<?xml version='1.0' encoding='utf-8'?>
<robot name="panda_default">
  <link name="world" />
  <joint name="main_joint_world" type="fixed">
    <parent link="world" />
    <child link="main_link" />
    <origin rpy="0 0 0" xyz="0 0 0" />
  </joint>
  <gazebo>
    <plugin filename="libgazebo_ros_control.so" name="gazebo_ros_control">
      <robotNamespace>/</robotNamespace>
    </plugin>
  </gazebo>
  <link name="main_link">
    </link>
  
  <joint name="panda_joint_main_link" type="fixed">
    <parent link="main_link" />
    <child link="panda_link0" />
    <origin rpy="0 0 0" xyz="0 0 0" />
  </joint>
  
  <gazebo reference="panda_link0" />
  <gazebo reference="panda_link1" />
  <gazebo reference="panda_link2" />
  <gazebo reference="panda_link3" />
  <gazebo reference="panda_link4" />
  <gazebo reference="panda_link5" />
  <gazebo reference="panda_link6" />
  <gazebo reference="panda_link7" />
  <gazebo reference="panda_link8" />
  <transmission name="panda_joint1_trans">
    <type>transmission_interface/SimpleTransmission</type>
    <joint name="panda_joint1">
      <hardwareInterface>hardware_interface/PositionJointInterface</hardwareInterface>
    </joint>
    <actuator name="panda_joint1_motor">
      <mechanicalReduction>1</mechanicalReduction>
    </actuator>
  </transmission>
  <transmission name="panda_joint2_trans">
    <type>transmission_interface/SimpleTransmission</type>
    <joint name="panda_joint2">
      <hardwareInterface>hardware_interface/PositionJointInterface</hardwareInterface>
    </joint>
    <actuator name="panda_joint2_motor">
      <mechanicalReduction>1</mechanicalReduction>
    </actuator>
  </transmission>
  <transmission name="panda_joint3_trans">
    <type>transmission_interface/SimpleTransmission</type>
    <joint name="panda_joint3">
      <hardwareInterface>hardware_interface/PositionJointInterface</hardwareInterface>
    </joint>
    <actuator name="panda_joint3_motor">
      <mechanicalReduction>1</mechanicalReduction>
    </actuator>
  </transmission>
  <transmission name="panda_joint4_trans">
    <type>transmission_interface/SimpleTransmission</type>
    <joint name="panda_joint4">
      <hardwareInterface>hardware_interface/PositionJointInterface</hardwareInterface>
    </joint>
    <actuator name="panda_joint4_motor">
      <mechanicalReduction>1</mechanicalReduction>
    </actuator>
  </transmission>
  <transmission name="panda_joint5_trans">
    <type>transmission_interface/SimpleTransmission</type>
    <joint name="panda_joint5">
      <hardwareInterface>hardware_interface/PositionJointInterface</hardwareInterface>
    </joint>
    <actuator name="panda_joint5_motor">
      <mechanicalReduction>1</mechanicalReduction>
    </actuator>
  </transmission>
  <transmission name="panda_joint6_trans">
    <type>transmission_interface/SimpleTransmission</type>
    <joint name="panda_joint6">
      <hardwareInterface>hardware_interface/PositionJointInterface</hardwareInterface>
    </joint>
    <actuator name="panda_joint6_motor">
      <mechanicalReduction>1</mechanicalReduction>
    </actuator>
  </transmission>
  <transmission name="panda_joint7_trans">
    <type>transmission_interface/SimpleTransmission</type>
    <joint name="panda_joint7">
      <hardwareInterface>hardware_interface/PositionJointInterface</hardwareInterface>
    </joint>
    <actuator name="panda_joint7_motor">
      <mechanicalReduction>1</mechanicalReduction>
    </actuator>
  </transmission>
  <link name="panda_link0">
    <inertial>
      
      <origin rpy="0 0 0" xyz="-0.041018 -0.00014 0.049974" />
      <mass value="0.629769" />
      <inertia ixx="0.00315" ixy="8.2904E-07" ixz="0.00015" iyy="0.00388" iyz="8.2299E-06" izz="0.004285" />
    </inertial>
    <visual>
      <origin rpy="0 0 0" xyz="0 0 0" />
      <geometry>
        <mesh filename="file://@URDF_DESTINATION@/meshes/visual/link0.dae" />
      </geometry>
      <material name="">
        <color rgba="1 1 1 1" />
      </material>
    </visual>
    <collision>
      <origin rpy="0 1.5707963267948966 0" xyz="-0.075 0 0.06" />
      <geometry>
        <cylinder length="0.03" radius="0.09" />
      </geometry>
    </collision>
    <collision>
      <origin rpy="0 0 0" xyz="-0.06 0 0.06" />
      <geometry>
        <sphere radius="0.09" />
      </geometry>
    </collision>
    <collision>
      <origin rpy="0 0 0" xyz="-0.09 0 0.06" />
      <geometry>
        <sphere radius="0.09" />
      </geometry>
    </collision>
  </link>
  <link name="panda_link1">
    <inertial>
      <origin rpy="0 0 0" xyz="0.003875 0.002081 -0.04762" />
      <mass value="4.970684" />
      <inertia ixx="0.70337" ixy="-0.00013900" ixz="0.0067720" iyy="0.70661" iyz="0.019169" izz="0.0091170" />
    </inertial>
    <visual>
      <origin rpy="0 0 0" xyz="0 0 0" />
      <geometry>
        <mesh filename="file://@URDF_DESTINATION@/meshes/visual/link1.dae" />
      </geometry>
      <material name="">
        <color rgba="1 1 1 1" />
      </material>
    </visual>
    <collision>
      <origin rpy="0 0 0" xyz="0 0 -0.1915" />
      <geometry>
        <cylinder length="0.2830" radius="0.09" />
      </geometry>
    </collision>
    <collision>
      <origin rpy="0 0 0" xyz="0 0 -0.333" />
      <geometry>
        <sphere radius="0.09" />
      </geometry>
    </collision>
    <collision>
      <origin rpy="0 0 0" xyz="0 0 -0.05" />
      <geometry>
        <sphere radius="0.09" />
      </geometry>
    </collision>
  </link>
  <joint name="panda_joint1" type="revolute">
    <safety_controller k_position="100.0" k_velocity="40.0" soft_lower_limit="-2.8973" soft_upper_limit="2.8973" />
    <origin rpy="2.5709246441992588e-17 -6.794078693010464e-18 -4.1227050414925375e-17" xyz="-8.936189539740361e-18 -8.332053651435081e-17 0.333" />
    <parent link="panda_link0" />
    <child link="panda_link1" />
    <axis xyz="0 0 1" />
    <limit effort="87" lower="-2.8973" upper="2.8973" velocity="2.1750" />
  </joint>
  <link name="panda_link2">
    <inertial>
      <origin rpy="0 0 0" xyz=" -0.003141 -0.02872  0.003495" />
      <mass value="0.646926" />
      <inertia ixx="0.0079620" ixy="-3.9250e-3" ixz="1.0254e-02" iyy="2.8110e-02" iyz="7.0400e-04" izz="2.5995e-02" />
    </inertial>
    <visual>
      <origin rpy="0 0 0" xyz="0 0 0" />
      <geometry>
        <mesh filename="file://@URDF_DESTINATION@/meshes/visual/link2.dae" />
      </geometry>
      <material name="">
        <color rgba="1 1 1 1" />
      </material>
    </visual>
    <collision>
      <origin rpy="0 0 0" xyz="0 0 0" />
      <geometry>
        <cylinder length="0.12" radius="0.09" />
      </geometry>
    </collision>
    <collision>
      <origin rpy="0 0 0" xyz="0 0 -0.06" />
      <geometry>
        <sphere radius="0.09" />
      </geometry>
    </collision>
    <collision>
      <origin rpy="0 0 0" xyz="0 0 0.06" />
      <geometry>
        <sphere radius="0.09" />
      </geometry>
    </collision>
  </link>
  <joint name="panda_joint2" type="revolute">
    <safety_controller k_position="100.0" k_velocity="40.0" soft_lower_limit="-1.7628" soft_upper_limit="1.7628" />
    <origin rpy="-1.5673253860674152 0.0011071496499899783 -1.8537306800931152e-07" xyz="-0.00032529091122156895 0.00017932808534245606 1.2005347165728229e-18" />
    <parent link="panda_link1" />
    <child link="panda_link2" />
    <axis xyz="0 0 1" />
    <limit effort="87" lower="-1.7628" upper="1.7628" velocity="2.1750" />
  </joint>
  <link name="panda_link3">
    <inertial>
      <origin rpy="0 0 0" xyz="2.7518e-02 3.9252e-02 -6.6502e-02" />
      <mass value="3.228604" />
      <inertia ixx="3.7242e-02" ixy="-4.7610e-03" ixz="-1.1396e-02" iyy="3.6155e-02" iyz="-1.2805e-02" izz="1.0830e-02" />
    </inertial>
    <visual>
      <origin rpy="0 0 0" xyz="0 0 0" />
      <geometry>
        <mesh filename="file://@URDF_DESTINATION@/meshes/visual/link3.dae" />
      </geometry>
      <material name="">
        <color rgba="1 1 1 1" />
      </material>
    </visual>
    <collision>
      <origin rpy="0 0 0" xyz="0 0 -0.145" />
      <geometry>
        <cylinder length="0.15" radius="0.09" />
      </geometry>
    </collision>
    <collision>
      <origin rpy="0 0 0" xyz="0 0 -0.22" />
      <geometry>
        <sphere radius="0.09" />
      </geometry>
    </collision>
    <collision>
      <origin rpy="0 0 0" xyz="0 0 -0.07" />
      <geometry>
        <sphere radius="0.09" />
      </geometry>
    </collision>
  </link>
  <joint name="panda_joint3" type="revolute">
    <safety_controller k_position="100.0" k_velocity="40.0" soft_lower_limit="-2.8973" soft_upper_limit="2.8973" />
    <origin rpy="1.5687136289781762 -9.51317661379261e-05 0.0010011478138700679" xyz="0.00033612710048449386 -0.31680578669840587 0.0001791112051231983" />
    <parent link="panda_link2" />
    <child link="panda_link3" />
    <axis xyz="0 0 1" />
    <limit effort="87" lower="-2.8973" upper="2.8973" velocity="2.1750" />
  </joint>
  <link name="panda_link4">
    <inertial>
      <origin rpy="0 0 0" xyz="-5.317e-02 1.04419e-01 2.7454e-02" />
      <mass value="3.587895" />
      <inertia ixx="2.5853e-02" ixy="7.7960e-03" ixz="-1.3320e-03" iyy="1.9552e-02" iyz="8.6410e-03" izz="2.8323e-02" />
    </inertial>
    <visual>
      <origin rpy="0 0 0" xyz="0 0 0" />
      <geometry>
        <mesh filename="file://@URDF_DESTINATION@/meshes/visual/link4.dae" />
      </geometry>
      <material name="">
        <color rgba="1 1 1 1" />
      </material>
    </visual>
    <collision>
      <origin rpy="0 0 0" xyz="0 0 0" />
      <geometry>
        <cylinder length="0.12" radius="0.09" />
      </geometry>
    </collision>
    <collision>
      <origin rpy="0 0 0" xyz="0 0 0.06" />
      <geometry>
        <sphere radius="0.09" />
      </geometry>
    </collision>
    <collision>
      <origin rpy="0 0 0" xyz="0 0 -0.06" />
      <geometry>
        <sphere radius="0.09" />
      </geometry>
    </collision>
  </link>
  <joint name="panda_joint4" type="revolute">
    <safety_controller k_position="100.0" k_velocity="40.0" soft_lower_limit="-3.0718" soft_upper_limit="-0.0698" />
    <origin rpy="1.574568879118156 0.005620013589583366 0.0001314581436195706" xyz="0.08291212727422625 -0.0004131994890023523 0.0008062352431686794" />
    <parent link="panda_link3" />
    <child link="panda_link4" />
    <axis xyz="0 0 1" />
    <limit effort="87" lower="-3.0718" upper="-0.0698" velocity="2.1750" />
  </joint>
  <link name="panda_link5">
    <inertial>
      <origin rpy="0 0 0" xyz="-1.1953e-02 4.1065e-02 -3.8437e-02" />
      <mass value="1.225946" />
      <inertia ixx="3.5549e-02" ixy="-2.1170e-03" ixz="-4.0370e-03" iyy="2.9474e-02" iyz="2.2900e-04" izz="8.6270e-03" />
    </inertial>
    <visual>
      <origin rpy="0 0 0" xyz="0 0 0" />
      <geometry>
        <mesh filename="file://@URDF_DESTINATION@/meshes/visual/link5.dae" />
      </geometry>
      <material name="">
        <color rgba="1 1 1 1" />
      </material>
    </visual>
    <collision>
      <origin rpy="0 0 0" xyz="0 0 -0.26" />
      <geometry>
        <cylinder length="0.1" radius="0.09" />
      </geometry>
    </collision>
    <collision>
      <origin rpy="0 0 0" xyz="0 0 -0.31" />
      <geometry>
        <sphere radius="0.09" />
      </geometry>
    </collision>
    <collision>
      <origin rpy="0 0 0" xyz="0 0 -0.21" />
      <geometry>
        <sphere radius="0.09" />
      </geometry>
    </collision>
    <collision>
      <origin rpy="0 0 0" xyz="0 0.08 -0.13" />
      <geometry>
        <cylinder length="0.14" radius="0.055" />
      </geometry>
    </collision>
    <collision>
      <origin rpy="0 0 0" xyz="0 0.08 -0.06" />
      <geometry>
        <sphere radius="0.055" />
      </geometry>
    </collision>
    <collision>
      <origin rpy="0 0 0" xyz="0 0.08 -0.20" />
      <geometry>
        <sphere radius="0.055" />
      </geometry>
    </collision>
  </link>
  <joint name="panda_joint5" type="revolute">
    <safety_controller k_position="100.0" k_velocity="40.0" soft_lower_limit="-2.8973" soft_upper_limit="2.8973" />
    <origin rpy="-1.5708152710066416 0.006346287018054772 -0.005015740883944844" xyz="-0.08112951114598124 0.3849785522971729 0.00041219356597207296" />
    <parent link="panda_link4" />
    <child link="panda_link5" />
    <axis xyz="0 0 1" />
    <limit effort="12" lower="-2.8973" upper="2.8973" velocity="2.6100" />
  </joint>
  <link name="panda_link6">
    <inertial>
      <origin rpy="0 0 0" xyz="6.0149e-02 -1.4117e-02 -1.0517e-02" />
      <mass value="1.666555" />
      <inertia ixx="1.9640e-03" ixy="1.0900e-04" ixz="-1.1580e-03" iyy="4.3540e-03" iyz="3.4100e-04" izz="5.4330e-03" />
    </inertial>
    <visual>
      <origin rpy="0 0 0" xyz="0 0 0" />
      <geometry>
        <mesh filename="file://@URDF_DESTINATION@/meshes/visual/link6.dae" />
      </geometry>
      <material name="">
        <color rgba="1 1 1 1" />
      </material>
    </visual>
    <collision>
      <origin rpy="0 0 0" xyz="0 0 -0.03" />
      <geometry>
        <cylinder length="0.08" radius="0.08" />
      </geometry>
    </collision>
    <collision>
      <origin rpy="0 0 0" xyz="0 0 0.01" />
      <geometry>
        <sphere radius="0.08" />
      </geometry>
    </collision>
    <collision>
      <origin rpy="0 0 0" xyz="0 0 -0.07" />
      <geometry>
        <sphere radius="0.08" />
      </geometry>
    </collision>
  </link>
  <joint name="panda_joint6" type="revolute">
    <safety_controller k_position="100.0" k_velocity="40.0" soft_lower_limit="-0.0175" soft_upper_limit="3.7525" />
    <origin rpy="1.566990752278219 -8.74664740810682e-06 0.0063468208926020005" xyz="-0.00038526921110553083 0.00018454755899632546 0.0009885555105147402" />
    <parent link="panda_link5" />
    <child link="panda_link6" />
    <axis xyz="0 0 1" />
    <limit effort="12" lower="-0.0175" upper="3.7525" velocity="2.6100" />
  </joint>
  <link name="panda_link7">
    <inertial>
      <origin rpy="0 0 0" xyz="1.0517e-02 -4.252e-03 6.1597e-02" />
      <mass value="7.35522e-01" />
      <inertia ixx="1.2516e-02" ixy="-4.2800e-04" ixz="-1.1960e-03" iyy="1.0027e-02" iyz="-7.4100e-04" izz="4.8150e-03" />
    </inertial>
    <visual>
      <origin rpy="0 0 0" xyz="0 0 0" />
      <geometry>
        <mesh filename="file://@URDF_DESTINATION@/meshes/visual/link7.dae" />
      </geometry>
      <material name="">
        <color rgba="1 1 1 1" />
      </material>
    </visual>
    <collision>
      <origin rpy="0 0 0" xyz="0 0 0.01" />
      <geometry>
        <cylinder length="0.14" radius="0.07" />
      </geometry>
    </collision>
    <collision>
      <origin rpy="0 0 0" xyz="0 0 0.08" />
      <geometry>
        <sphere radius="0.07" />
      </geometry>
    </collision>
    <collision>
      <origin rpy="0 0 0" xyz="0 0 -0.06" />
      <geometry>
        <sphere radius="0.07" />
      </geometry>
    </collision>
  </link>
  <joint name="panda_joint7" type="revolute">
    <safety_controller k_position="100.0" k_velocity="40.0" soft_lower_limit="-2.8973" soft_upper_limit="2.8973" />
    <origin rpy="1.5709898110979406 4.088505162405892e-08 3.302677451850414e-05" xyz="0.08730954961859545 -1.5022321236779503e-07 -0.00018132573202604788" />
    <parent link="panda_link6" />
    <child link="panda_link7" />
    <axis xyz="0 0 1" />
    <limit effort="12" lower="-2.8973" upper="2.8973" velocity="2.6100" />
  </joint>
  <link name="panda_link8">
    <collision>
      <origin rpy="3.141592653589793 1.5707963267948966 1.5707963267948966" xyz="0.0424 0.0424 -0.0250" />
      <geometry>
        <cylinder length="0.01" radius="0.06" />
      </geometry>
    </collision>
    <collision>
      <origin rpy="0 0 0" xyz="0.0424 0.0424 -0.02" />
      <geometry>
        <sphere radius="0.06" />
      </geometry>
    </collision>
    <collision>
      <origin rpy="0 0 0" xyz="0.0424 0.0424 -0.03" />
      <geometry>
        <sphere radius="0.06" />
      </geometry>
    </collision>
  </link>
  <joint name="panda_joint8" type="fixed">
    <origin rpy="0 0 0" xyz="0 0 0.107" />
    <parent link="panda_link7" />
    <child link="panda_link8" />
    <axis xyz="0 0 0" />
  </joint>
  <link name="ball_link">
    <visual>
      <material name="red">
        <color rgba="1 0 0 1" />
      </material>

      <geometry>
        <sphere radius="0.005" />
      </geometry>
    </visual>
  </link>

  <joint name="ball_joint" type="fixed">
    <origin rpy="0.0 0.0 0.0" xyz="-5.081072879362442e-05 -0.0005746107137692017 0.07524678614749795" />
    <parent link="panda_link8" />
    <child link="ball_link" />
  </joint>
</robot>
